Workbook

Sheet Data
A1: order_id | B1: customer_state | C1: purchase_date | D1: delivered_date | E1: estimated_date | F1: product_category | G1: price | H1: freight_value | I1: payment_type | J1: review_score | K1: order_status | L1: order_month | M1: delivery_days | N1: delay_days | O1: on_time | P1: revenue | Q1: cogs | R1: freight_absorbed | S1: net_profit | T1: delivery_bucket | W1: sort_after_unique_using_sortby
A2: ad3e8705cd525f9feb67a72c8ee0314d | B2: SP | C2: 45294 | D2: 45304 | E2: 45308 | F2: toys | G2: 83.12 | H2: 19.21 | I2: credit_card | J2: 5 | K2: delivered | L2: =DATE(YEAR(C2),MONTH(C2),1) -> 45292 | M2: =D2-C2 -> 10 | N2: =MAX(0,D2-E2) -> 0 | O2: =IF(D2<=E2,1,0) -> 1 | P2: =G2+H2 -> 102.33 | Q2: =G2*INDEX(Assumptions!$B$8:$B$16,MATCH(F2,Assumptions!$A$8:$A$16,0)) -> 49.872 | R2: =H2*Assumptions!$B$3 -> 11.526 | S2: =G2-Q2-R2 -> 21.722 | T2: =IF(M2<=7,"0-7 days",IF(M2<=14,"8-14 days",IF(M2<=21,"15-21 days","22+ days"))) -> 8-14 days | W2: {=_xlfn.UNIQUE(B:B)} -> customer_state | AH2: profit_margin | AI2: avg_friedight_delivery_charges | AJ2: order_percentage_on_time | AK2: state_order_delivered _on_time | AL2: in_percentage/total_order | AM2: rank_fucntion_base_on_NO_orders
A3: 63b55bfb128e92ad6b707ef6fe62314e | B3: PR | C3: 45294 | D3: 45306 | E3: 45317 | F3: health_beauty | G3: 60.51 | H3: 16.47 | I3: voucher | J3: 4 | K3: delivered | L3: =DATE(YEAR(C3),MONTH(C3),1) -> 45292 | M3: =D3-C3 -> 12 | N3: =MAX(0,D3-E3) -> 0 | O3: =IF(D3<=E3,1,0) -> 1 | P3: =G3+H3 -> 76.98 | Q3: =G3*INDEX(Assumptions!$B$8:$B$16,MATCH(F3,Assumptions!$A$8:$A$16,0)) -> 35.0958 | R3: =H3*Assumptions!$B$3 -> 9.882 | S3: =G3-Q3-R3 -> 15.5322 | T3: =IF(M3<=7,"0-7 days",IF(M3<=14,"8-14 days",IF(M3<=21,"15-21 days","22+ days"))) -> 8-14 days | W3: SP | X3: =COUNTIF(B2:B2001,W3) -> 909 | Z3: {=_xlfn.SORTBY(W3:W14,X3:X14,-1)} -> SP | AB3: {=_xlfn.SORTBY(W3:X14,X3:X14,-1)} -> SP | AC3: 909 | AD3: =AC3/$AC$15 -> 0.4545 | AE3: =SUMIF(AB3:AB14,AB3,P2:P2001) -> 102.33 | AF3: =SUMIF(B:B,AB3,P:P) -> 115617.11 | AG3: =SUMIFS(S:S,B:B,AB3) -> 25250.604 | AH3: =AG3/AF3*100 -> 21.839851 | AI3: =AVERAGEIF(B:B,AB3,H:H) -> 17.822387 | AJ3: =COUNTIF(O:O,1) -> 1855 | AK3: =SUMIF(B:B,AB3,O:O) -> 860 | AL3: =AK3/AC3 -> 0.94609461 | AM3: =RANK(AC3,$AC$3:$AC$14) -> 1
A4: c18cc4131d848484424526028f016e18 | B4: RS | C4: 45294 | D4: 45316 | E4: 45320 | F4: computers_accessories | G4: 134.74 | H4: 25 | I4: credit_card | J4: 3 | K4: delivered | L4: =DATE(YEAR(C4),MONTH(C4),1) -> 45292 | M4: =D4-C4 -> 22 | N4: =MAX(0,D4-E4) -> 0 | O4: =IF(D4<=E4,1,0) -> 1 | P4: =G4+H4 -> 159.74 | Q4: =G4*INDEX(Assumptions!$B$8:$B$16,MATCH(F4,Assumptions!$A$8:$A$16,0)) -> 99.7076 | R4: =H4*Assumptions!$B$3 -> 15 | S4: =G4-Q4-R4 -> 20.0324 | T4: =IF(M4<=7,"0-7 days",IF(M4<=14,"8-14 days",IF(M4<=21,"15-21 days","22+ days"))) -> 22+ days | W4: PR | X4: =COUNTIF(B3:B2002,W4) -> 115 | Z4: RJ | AB4: RJ | AC4: 252 | AD4: =AC4/$AC$15 -> 0.126 | AE4: =SUMIF(AB4:AB15,AB4,P3:P2002) -> 76.98 | AF4: =SUMIF(B:B,AB4,P:P) -> 32089.61 | AG4: =SUMIFS(S:S,B:B,AB4) -> 5451.465 | AH4: =AG4/AF4*100 -> 16.988256 | AI4: =AVERAGEIF(B:B,AB4,H:H) -> 23.998294 | AJ4: order_percentage_on_time | AK4: =SUMIF(B:B,AB4,O:O) -> 227 | AL4: =AK4/AC4 -> 0.90079365 | AM4: =RANK(AC4,$AC$3:$AC$14) -> 2
A5: e88188c3788f06ed3c1e919bee5a4007 | B5: RJ | C5: 45296 | D5: 45310 | E5: 45319 | F5: computers_accessories | G5: 40.74 | H5: 16.28 | I5: credit_card | J5: 5 | K5: delivered | L5: =DATE(YEAR(C5),MONTH(C5),1) -> 45292 | M5: =D5-C5 -> 14 | N5: =MAX(0,D5-E5) -> 0 | O5: =IF(D5<=E5,1,0) -> 1 | P5: =G5+H5 -> 57.02 | Q5: =G5*INDEX(Assumptions!$B$8:$B$16,MATCH(F5,Assumptions!$A$8:$A$16,0)) -> 30.1476 | R5: =H5*Assumptions!$B$3 -> 9.768 | S5: =G5-Q5-R5 -> 0.8244 | T5: =IF(M5<=7,"0-7 days",IF(M5<=14,"8-14 days",IF(M5<=21,"15-21 days","22+ days"))) -> 8-14 days | W5: RS | X5: =COUNTIF(B4:B2003,W5) -> 110 | Z5: MG | AB5: MG | AC5: 241 | AD5: =AC5/$AC$15 -> 0.1205 | AE5: =SUMIF(AB5:AB16,AB5,P4:P2003) -> 159.74 | AF5: =SUMIF(B:B,AB5,P:P) -> 31045.7 | AG5: =SUMIFS(S:S,B:B,AB5) -> 5486.7233 | AH5: =AG5/AF5*100 -> 17.673054 | AI5: =AVERAGEIF(B:B,AB5,H:H) -> 23.306349 | AJ5: =COUNTIF(O:O,0) -> 145 | AK5: =SUMIF(B:B,AB5,O:O) -> 231 | AL5: =AK5/AC5 -> 0.95850622 | AM5: =RANK(AC5,$AC$3:$AC$14) -> 3
A6: b789593e216dfc7021965beeda3544b5 | B6: SP | C6: 45296 | D6: 45310 | E6: 45313 | F6: auto | G6: 47.62 | H6: 13.02 | I6: credit_card | J6: 5 | K6: delivered | L6: =DATE(YEAR(C6),MONTH(C6),1) -> 45292 | M6: =D6-C6 -> 14 | N6: =MAX(0,D6-E6) -> 0 | O6: =IF(D6<=E6,1,0) -> 1 | P6: =G6+H6 -> 60.64 | Q6: =G6*INDEX(Assumptions!$B$8:$B$16,MATCH(F6,Assumptions!$A$8:$A$16,0)) -> 32.3816 | R6: =H6*Assumptions!$B$3 -> 7.812 | S6: =G6-Q6-R6 -> 7.4264 | T6: =IF(M6<=7,"0-7 days",IF(M6<=14,"8-14 days",IF(M6<=21,"15-21 days","22+ days"))) -> 8-14 days | W6: RJ | X6: =COUNTIF(B5:B2004,W6) -> 252 | Z6: PR | AB6: PR | AC6: 115 | AD6: =AC6/$AC$15 -> 0.0575 | AE6: =SUMIF(AB6:AB17,AB6,P5:P2004) -> 57.02 | AF6: =SUMIF(B:B,AB6,P:P) -> 16873.04 | AG6: =SUMIFS(S:S,B:B,AB6) -> 3163.2744 | AH6: =AG6/AF6*100 -> 18.747507 | AI6: =AVERAGEIF(B:B,AB6,H:H) -> 23.454522 | AK6: =SUMIF(B:B,AB6,O:O) -> 102 | AL6: =AK6/AC6 -> 0.88695652 | AM6: =RANK(AC6,$AC$3:$AC$14) -> 4
A7: 912cf322735e81531c3892e8f2cfcd63 | B7: RS | C7: 45297 | D7: 45313 | E7: 45321 | F7: sports_leisure | G7: 125.89 | H7: 20.72 | I7: boleto | J7: 4 | K7: delivered | L7: =DATE(YEAR(C7),MONTH(C7),1) -> 45292 | M7: =D7-C7 -> 16 | N7: =MAX(0,D7-E7) -> 0 | O7: =IF(D7<=E7,1,0) -> 1 | P7: =G7+H7 -> 146.61 | Q7: =G7*INDEX(Assumptions!$B$8:$B$16,MATCH(F7,Assumptions!$A$8:$A$16,0)) -> 80.5696 | R7: =H7*Assumptions!$B$3 -> 12.432 | S7: =G7-Q7-R7 -> 32.8884 | T7: =IF(M7<=7,"0-7 days",IF(M7<=14,"8-14 days",IF(M7<=21,"15-21 days","22+ days"))) -> 15-21 days | W7: MG | X7: =COUNTIF(B6:B2005,W7) -> 241 | Z7: RS | AB7: RS | AC7: 110 | AD7: =AC7/$AC$15 -> 0.055 | AE7: =SUMIF(AB7:AB18,AB7,P6:P2005) -> 60.64 | AF7: =SUMIF(B:B,AB7,P:P) -> 15610.33 | AG7: =SUMIFS(S:S,B:B,AB7) -> 2729.7099 | AH7: =AG7/AF7*100 -> 17.486561 | AI7: =AVERAGEIF(B:B,AB7,H:H) -> 24.362 | AK7: =SUMIF(B:B,AB7,O:O) -> 96 | AL7: =AK7/AC7 -> 0.87272727 | AM7: =RANK(AC7,$AC$3:$AC$14) -> 5
A8: 14a9ee59eb1313b795d14b6d6e9ae156 | B8: MG | C8: 45300 | D8: 45317 | E8: 45323 | F8: auto | G8: 119.5 | H8: 26.65 | I8: credit_card | J8: 4 | K8: delivered | L8: =DATE(YEAR(C8),MONTH(C8),1) -> 45292 | M8: =D8-C8 -> 17 | N8: =MAX(0,D8-E8) -> 0 | O8: =IF(D8<=E8,1,0) -> 1 | P8: =G8+H8 -> 146.15 | Q8: =G8*INDEX(Assumptions!$B$8:$B$16,MATCH(F8,Assumptions!$A$8:$A$16,0)) -> 81.26 | R8: =H8*Assumptions!$B$3 -> 15.99 | S8: =G8-Q8-R8 -> 22.25 | T8: =IF(M8<=7,"0-7 days",IF(M8<=14,"8-14 days",IF(M8<=21,"15-21 days","22+ days"))) -> 15-21 days | W8: ES | X8: =COUNTIF(B7:B2006,W8) -> 33 | Z8: SC | AB8: SC | AC8: 96 | AD8: =AC8/$AC$15 -> 0.048 | AE8: =SUMIF(AB8:AB19,AB8,P7:P2006) -> 146.61 | AF8: =SUMIF(B:B,AB8,P:P) -> 13452.91 | AG8: =SUMIFS(S:S,B:B,AB8) -> 2562.6194 | AH8: =AG8/AF8*100 -> 19.048811 | AI8: =AVERAGEIF(B:B,AB8,H:H) -> 24.139896 | AK8: =SUMIF(B:B,AB8,O:O) -> 89 | AL8: =AK8/AC8 -> 0.92708333 | AM8: =RANK(AC8,$AC$3:$AC$14) -> 6
A9: 094f51660bae6d2bfbece5d5a8856294 | B9: SP | C9: 45300 | D9: 45317 | E9: 45319 | F9: watches_gifts | G9: 280.85 | H9: 22.93 | I9: credit_card | J9: 5 | K9: delivered | L9: =DATE(YEAR(C9),MONTH(C9),1) -> 45292 | M9: =D9-C9 -> 17 | N9: =MAX(0,D9-E9) -> 0 | O9: =IF(D9<=E9,1,0) -> 1 | P9: =G9+H9 -> 303.78 | Q9: =G9*INDEX(Assumptions!$B$8:$B$16,MATCH(F9,Assumptions!$A$8:$A$16,0)) -> 185.361 | R9: =H9*Assumptions!$B$3 -> 13.758 | S9: =G9-Q9-R9 -> 81.731 | T9: =IF(M9<=7,"0-7 days",IF(M9<=14,"8-14 days",IF(M9<=21,"15-21 days","22+ days"))) -> 15-21 days | W9: BA | X9: =COUNTIF(B8:B2007,W9) -> 65 | Z9: BA | AB9: BA | AC9: 65 | AD9: =AC9/$AC$15 -> 0.0325 | AE9: =SUMIF(AB9:AB20,AB9,P8:P2007) -> 146.15 | AF9: =SUMIF(B:B,AB9,P:P) -> 8267.86 | AG9: =SUMIFS(S:S,B:B,AB9) -> 937.0956 | AH9: =AG9/AF9*100 -> 11.334198 | AI9: =AVERAGEIF(B:B,AB9,H:H) -> 32.066308 | AK9: =SUMIF(B:B,AB9,O:O) -> 61 | AL9: =AK9/AC9 -> 0.93846154 | AM9: =RANK(AC9,$AC$3:$AC$14) -> 7
A10: 0534a1018ddce71981f38dd4fd034ada | B10: SP | C10: 45303 | D10: 45309 | E10: 45318 | F10: auto | G10: 42.07 | H10: 16.67 | I10: credit_card | J10: 4 | K10: delivered | L10: =DATE(YEAR(C10),MONTH(C10),1) -> 45292 | M10: =D10-C10 -> 6 | N10: =MAX(0,D10-E10) -> 0 | O10: =IF(D10<=E10,1,0) -> 1 | P10: =G10+H10 -> 58.74 | Q10: =G10*INDEX(Assumptions!$B$8:$B$16,MATCH(F10,Assumptions!$A$8:$A$16,0)) -> 28.6076 | R10: =H10*Assumptions!$B$3 -> 10.002 | S10: =G10-Q10-R10 -> 3.4604 | T10: =IF(M10<=7,"0-7 days",IF(M10<=14,"8-14 days",IF(M10<=21,"15-21 days","22+ days"))) -> 0-7 days | W10: DF | X10: =COUNTIF(B9:B2008,W10) -> 52 | Z10: GO | AB10: GO | AC10: 60 | AD10: =AC10/$AC$15 -> 0.03 | AE10: =SUMIF(AB10:AB21,AB10,P9:P2008) -> 303.78 | AF10: =SUMIF(B:B,AB10,P:P) -> 9527.25 | AG10: =SUMIFS(S:S,B:B,AB10) -> 1708.0977 | AH10: =AG10/AF10*100 -> 17.928549 | AI10: =AVERAGEIF(B:B,AB10,H:H) -> 26.811667 | AK10: =SUMIF(B:B,AB10,O:O) -> 49 | AL10: =AK10/AC10 -> 0.81666667 | AM10: =RANK(AC10,$AC$3:$AC$14) -> 8
A11: 8ff63d7ed92fcf511e8124950bd515dd | B11: MG | C11: 45303 | D11: 45314 | E11: 45325 | F11: bed_bath_table | G11: 83.04 | H11: 23.66 | I11: credit_card | J11: 4 | K11: delivered | L11: =DATE(YEAR(C11),MONTH(C11),1) -> 45292 | M11: =D11-C11 -> 11 | N11: =MAX(0,D11-E11) -> 0 | O11: =IF(D11<=E11,1,0) -> 1 | P11: =G11+H11 -> 106.7 | Q11: =G11*INDEX(Assumptions!$B$8:$B$16,MATCH(F11,Assumptions!$A$8:$A$16,0)) -> 51.4848 | R11: =H11*Assumptions!$B$3 -> 14.196 | S11: =G11-Q11-R11 -> 17.3592 | T11: =IF(M11<=7,"0-7 days",IF(M11<=14,"8-14 days",IF(M11<=21,"15-21 days","22+ days"))) -> 8-14 days | W11: SC | X11: =COUNTIF(B10:B2009,W11) -> 96 | Z11: DF | AB11: DF | AC11: 52 | AD11: =AC11/$AC$15 -> 0.026 | AE11: =SUMIF(AB11:AB22,AB11,P10:P2009) -> 58.74 | AF11: =SUMIF(B:B,AB11,P:P) -> 7697.46 | AG11: =SUMIFS(S:S,B:B,AB11) -> 1537.265 | AH11: =AG11/AF11*100 -> 19.971068 | AI11: =AVERAGEIF(B:B,AB11,H:H) -> 24.015769 | AK11: =SUMIF(B:B,AB11,O:O) -> 50 | AL11: =AK11/AC11 -> 0.96153846 | AM11: =RANK(AC11,$AC$3:$AC$14) -> 9
A12: e3f2df80a7bbc6129a37ef9d5983ce94 | B12: SP | C12: 45305 | D12: 45317 | E12: 45321 | F12: watches_gifts | G12: 96.56 | H12: 12.89 | I12: credit_card | J12: 4 | K12: delivered | L12: =DATE(YEAR(C12),MONTH(C12),1) -> 45292 | M12: =D12-C12 -> 12 | N12: =MAX(0,D12-E12) -> 0 | O12: =IF(D12<=E12,1,0) -> 1 | P12: =G12+H12 -> 109.45 | Q12: =G12*INDEX(Assumptions!$B$8:$B$16,MATCH(F12,Assumptions!$A$8:$A$16,0)) -> 63.7296 | R12: =H12*Assumptions!$B$3 -> 7.734 | S12: =G12-Q12-R12 -> 25.0964 | T12: =IF(M12<=7,"0-7 days",IF(M12<=14,"8-14 days",IF(M12<=21,"15-21 days","22+ days"))) -> 8-14 days | W12: GO | X12: =COUNTIF(B11:B2010,W12) -> 60 | Z12: PE | AB12: PE | AC12: 42 | AD12: =AC12/$AC$15 -> 0.021 | AE12: =SUMIF(AB12:AB23,AB12,P11:P2010) -> 106.7 | AF12: =SUMIF(B:B,AB12,P:P) -> 6527.81 | AG12: =SUMIFS(S:S,B:B,AB12) -> 787.2045 | AH12: =AG12/AF12*100 -> 12.059243 | AI12: =AVERAGEIF(B:B,AB12,H:H) -> 37.270714 | AK12: =SUMIF(B:B,AB12,O:O) -> 38 | AL12: =AK12/AC12 -> 0.9047619 | AM12: =RANK(AC12,$AC$3:$AC$14) -> 10
A13: c1f857c42726c2c37af468fdfa6965f1 | B13: SP | C13: 45307 | D13: 45316 | E13: 45324 | F13: sports_leisure | G13: 40.63 | H13: 17.32 | I13: boleto | J13: 4 | K13: delivered | L13: =DATE(YEAR(C13),MONTH(C13),1) -> 45292 | M13: =D13-C13 -> 9 | N13: =MAX(0,D13-E13) -> 0 | O13: =IF(D13<=E13,1,0) -> 1 | P13: =G13+H13 -> 57.95 | Q13: =G13*INDEX(Assumptions!$B$8:$B$16,MATCH(F13,Assumptions!$A$8:$A$16,0)) -> 26.0032 | R13: =H13*Assumptions!$B$3 -> 10.392 | S13: =G13-Q13-R13 -> 4.2348 | T13: =IF(M13<=7,"0-7 days",IF(M13<=14,"8-14 days",IF(M13<=21,"15-21 days","22+ days"))) -> 8-14 days | W13: PE | X13: =COUNTIF(B12:B2011,W13) -> 42 | Z13: ES | AB13: ES | AC13: 33 | AD13: =AC13/$AC$15 -> 0.0165 | AE13: =SUMIF(AB13:AB24,AB13,P12:P2011) -> 109.45 | AF13: =SUMIF(B:B,AB13,P:P) -> 4059.07 | AG13: =SUMIFS(S:S,B:B,AB13) -> 680.598 | AH13: =AG13/AF13*100 -> 16.767338 | AI13: =AVERAGEIF(B:B,AB13,H:H) -> 25.128182 | AK13: =SUMIF(B:B,AB13,O:O) -> 28 | AL13: =AK13/AC13 -> 0.84848485 | AM13: =RANK(AC13,$AC$3:$AC$14) -> 11
A14: 582d1e50fda6d97117bd21248a994696 | B14: SP | C14: 45309 | D14: 45315 | E14: 45326 | F14: toys | G14: 60.84 | H14: 20.58 | I14: credit_card | J14: 5 | K14: delivered | L14: =DATE(YEAR(C14),MONTH(C14),1) -> 45292 | M14: =D14-C14 -> 6 | N14: =MAX(0,D14-E14) -> 0 | O14: =IF(D14<=E14,1,0) -> 1 | P14: =G14+H14 -> 81.42 | Q14: =G14*INDEX(Assumptions!$B$8:$B$16,MATCH(F14,Assumptions!$A$8:$A$16,0)) -> 36.504 | R14: =H14*Assumptions!$B$3 -> 12.348 | S14: =G14-Q14-R14 -> 11.988 | T14: =IF(M14<=7,"0-7 days",IF(M14<=14,"8-14 days",IF(M14<=21,"15-21 days","22+ days"))) -> 0-7 days | W14: CE | X14: =COUNTIF(B13:B2012,W14) -> 25 | Z14: CE | AB14: CE | AC14: 25 | AD14: =AC14/$AC$15 -> 0.0125 | AE14: =SUMIF(AB14:AB25,AB14,P13:P2012) -> 57.95 | AF14: =SUMIF(B:B,AB14,P:P) -> 4157.51 | AG14: =SUMIFS(S:S,B:B,AB14) -> 561.9106 | AH14: =AG14/AF14*100 -> 13.515556 | AI14: =AVERAGEIF(B:B,AB14,H:H) -> 40.014 | AL14: =AK14/AC14 -> 0 | AM14: =RANK(AC14,$AC14:$AC$14) -> 1
A15: e6d7e5589a117c5a8d8957fb4a357184 | B15: SP | C15: 45311 | D15: 45315 | E15: 45328 | F15: sports_leisure | G15: 48.02 | H15: 15.63 | I15: credit_card | J15: 3 | K15: delivered | L15: =DATE(YEAR(C15),MONTH(C15),1) -> 45292 | M15: =D15-C15 -> 4 | N15: =MAX(0,D15-E15) -> 0 | O15: =IF(D15<=E15,1,0) -> 1 | P15: =G15+H15 -> 63.65 | Q15: =G15*INDEX(Assumptions!$B$8:$B$16,MATCH(F15,Assumptions!$A$8:$A$16,0)) -> 30.7328 | R15: =H15*Assumptions!$B$3 -> 9.378 | S15: =G15-Q15-R15 -> 7.9092 | T15: =IF(M15<=7,"0-7 days",IF(M15<=14,"8-14 days",IF(M15<=21,"15-21 days","22+ days"))) -> 0-7 days | W15: 0 | AC15: =SUM(AC3:AC14) -> 2000 | AF15: 1000 | AG15: 500 | AH15: =AF15/AG15 -> 2
A16: c53d1af98d40aeb2aed690cc037f5347 | B16: SP | C16: 45313 | D16: 45323 | E16: 45324 | F16: bed_bath_table | G16: 61.25 | H16: 12.74 | I16: boleto | J16: 5 | K16: delivered | L16: =DATE(YEAR(C16),MONTH(C16),1) -> 45292 | M16: =D16-C16 -> 10 | N16: =MAX(0,D16-E16) -> 0 | O16: =IF(D16<=E16,1,0) -> 1 | P16: =G16+H16 -> 73.99 | Q16: =G16*INDEX(Assumptions!$B$8:$B$16,MATCH(F16,Assumptions!$A$8:$A$16,0)) -> 37.975 | R16: =H16*Assumptions!$B$3 -> 7.644 | S16: =G16-Q16-R16 -> 15.631 | T16: =IF(M16<=7,"0-7 days",IF(M16<=14,"8-14 days",IF(M16<=21,"15-21 days","22+ days"))) -> 8-14 days
A17: e1e3db63ef7ddc76b92da22b21df306f | B17: MG | C17: 45314 | D17: 45327 | E17: 45338 | F17: bed_bath_table | G17: 33.18 | H17: 17.66 | I17: credit_card | J17: 4 | K17: delivered | L17: =DATE(YEAR(C17),MONTH(C17),1) -> 45292 | M17: =D17-C17 -> 13 | N17: =MAX(0,D17-E17) -> 0 | O17: =IF(D17<=E17,1,0) -> 1 | P17: =G17+H17 -> 50.84 | Q17: =G17*INDEX(Assumptions!$B$8:$B$16,MATCH(F17,Assumptions!$A$8:$A$16,0)) -> 20.5716 | R17: =H17*Assumptions!$B$3 -> 10.596 | S17: =G17-Q17-R17 -> 2.0124 | T17: =IF(M17<=7,"0-7 days",IF(M17<=14,"8-14 days",IF(M17<=21,"15-21 days","22+ days"))) -> 8-14 days
A18: 1aa6f7cb90c7e6aca3bfe403388c9751 | B18: SP | C18: 45314 | D18: 45327 | E18: 45335 | F18: bed_bath_table | G18: 250.5 | H18: 25.67 | I18: voucher | J18: 4 | K18: delivered | L18: =DATE(YEAR(C18),MONTH(C18),1) -> 45292 | M18: =D18-C18 -> 13 | N18: =MAX(0,D18-E18) -> 0 | O18: =IF(D18<=E18,1,0) -> 1 | P18: =G18+H18 -> 276.17 | Q18: =G18*INDEX(Assumptions!$B$8:$B$16,MATCH(F18,Assumptions!$A$8:$A$16,0)) -> 155.31 | R18: =H18*Assumptions!$B$3 -> 15.402 | S18: =G18-Q18-R18 -> 79.788 | T18: =IF(M18<=7,"0-7 days",IF(M18<=14,"8-14 days",IF(M18<=21,"15-21 days","22+ days"))) -> 8-14 days | AF18: Row Labels | AG18: Count of order_id
A19: 8f9afd511a58fa4437abaed786faaa83 | B19: SP | C19: 45314 | D19: 45319 | E19: 45326 | F19: toys | G19: 89.54 | H19: 18.61 | I19: credit_card | J19: 5 | K19: delivered | L19: =DATE(YEAR(C19),MONTH(C19),1) -> 45292 | M19: =D19-C19 -> 5 | N19: =MAX(0,D19-E19) -> 0 | O19: =IF(D19<=E19,1,0) -> 1 | P19: =G19+H19 -> 108.15 | Q19: =G19*INDEX(Assumptions!$B$8:$B$16,MATCH(F19,Assumptions!$A$8:$A$16,0)) -> 53.724 | R19: =H19*Assumptions!$B$3 -> 11.166 | S19: =G19-Q19-R19 -> 24.65 | T19: =IF(M19<=7,"0-7 days",IF(M19<=14,"8-14 days",IF(M19<=21,"15-21 days","22+ days"))) -> 0-7 days | AF19: SP | AG19: 909 | AH19: =GETPIVOTDATA("order_id",$AF$18,"customer_state","SP")/GETPIVOTDATA("order_id",$AF$18) -> 0.4545 | AK19: total_revenue
A20: 9b2d5a2a99bd6240a8535961632d0302 | B20: ES | C20: 45315 | D20: 45338 | E20: 45335 | F20: health_beauty | G20: 112.6 | H20: 19.63 | I20: boleto | J20: 3 | K20: delivered | L20: =DATE(YEAR(C20),MONTH(C20),1) -> 45292 | M20: =D20-C20 -> 23 | N20: =MAX(0,D20-E20) -> 3 | O20: =IF(D20<=E20,1,0) -> 0 | P20: =G20+H20 -> 132.23 | Q20: =G20*INDEX(Assumptions!$B$8:$B$16,MATCH(F20,Assumptions!$A$8:$A$16,0)) -> 65.308 | R20: =H20*Assumptions!$B$3 -> 11.778 | S20: =G20-Q20-R20 -> 35.514 | T20: =IF(M20<=7,"0-7 days",IF(M20<=14,"8-14 days",IF(M20<=21,"15-21 days","22+ days"))) -> 22+ days | AF20: RJ | AG20: 252
A21: f4184c807429a2029b4e4fb080081255 | B21: RJ | C21: 45323 | D21: 45353 | E21: 45347 | F21: furniture_decor | G21: 85.11 | H21: 25.44 | I21: boleto | J21: 3 | K21: delivered | L21: =DATE(YEAR(C21),MONTH(C21),1) -> 45323 | M21: =D21-C21 -> 30 | N21: =MAX(0,D21-E21) -> 6 | O21: =IF(D21<=E21,1,0) -> 0 | P21: =G21+H21 -> 110.55 | Q21: =G21*INDEX(Assumptions!$B$8:$B$16,MATCH(F21,Assumptions!$A$8:$A$16,0)) -> 59.577 | R21: =H21*Assumptions!$B$3 -> 15.264 | S21: =G21-Q21-R21 -> 10.269 | T21: =IF(M21<=7,"0-7 days",IF(M21<=14,"8-14 days",IF(M21<=21,"15-21 days","22+ days"))) -> 22+ days | AF21: MG | AG21: 241 | AK21: =SUM(P2:P2001) -> 264925.66
A22: af35fbc0e1057ec8ebf3ef9939d38f2b | B22: RJ | C22: 45324 | D22: 45334 | E22: 45345 | F22: bed_bath_table | G22: 62.55 | H22: 25.58 | I22: credit_card | J22: 4 | K22: delivered | L22: =DATE(YEAR(C22),MONTH(C22),1) -> 45323 | M22: =D22-C22 -> 10 | N22: =MAX(0,D22-E22) -> 0 | O22: =IF(D22<=E22,1,0) -> 1 | P22: =G22+H22 -> 88.13 | Q22: =G22*INDEX(Assumptions!$B$8:$B$16,MATCH(F22,Assumptions!$A$8:$A$16,0)) -> 38.781 | R22: =H22*Assumptions!$B$3 -> 15.348 | S22: =G22-Q22-R22 -> 8.421 | T22: =IF(M22<=7,"0-7 days",IF(M22<=14,"8-14 days",IF(M22<=21,"15-21 days","22+ days"))) -> 8-14 days | AF22: PR | AG22: 115
A23: 2b0f225c235ae03ad4b8a420ea5f05f4 | B23: RS | C23: 45324 | D23: 45334 | E23: 45353 | F23: watches_gifts | G23: 97.97 | H23: 27.76 | I23: credit_card | J23: 3 | K23: delivered | L23: =DATE(YEAR(C23),MONTH(C23),1) -> 45323 | M23: =D23-C23 -> 10 | N23: =MAX(0,D23-E23) -> 0 | O23: =IF(D23<=E23,1,0) -> 1 | P23: =G23+H23 -> 125.73 | Q23: =G23*INDEX(Assumptions!$B$8:$B$16,MATCH(F23,Assumptions!$A$8:$A$16,0)) -> 64.6602 | R23: =H23*Assumptions!$B$3 -> 16.656 | S23: =G23-Q23-R23 -> 16.6538 | T23: =IF(M23<=7,"0-7 days",IF(M23<=14,"8-14 days",IF(M23<=21,"15-21 days","22+ days"))) -> 8-14 days | AF23: RS | AG23: 110
A24: 1da8558369cb21419505d99e2f7d987d | B24: SP | C24: 45325 | D24: 45334 | E24: 45335 | F24: sports_leisure | G24: 70.84 | H24: 20.21 | I24: credit_card | J24: 5 | K24: delivered | L24: =DATE(YEAR(C24),MONTH(C24),1) -> 45323 | M24: =D24-C24 -> 9 | N24: =MAX(0,D24-E24) -> 0 | O24: =IF(D24<=E24,1,0) -> 1 | P24: =G24+H24 -> 91.05 | Q24: =G24*INDEX(Assumptions!$B$8:$B$16,MATCH(F24,Assumptions!$A$8:$A$16,0)) -> 45.3376 | R24: =H24*Assumptions!$B$3 -> 12.126 | S24: =G24-Q24-R24 -> 13.3764 | T24: =IF(M24<=7,"0-7 days",IF(M24<=14,"8-14 days",IF(M24<=21,"15-21 days","22+ days"))) -> 8-14 days | AF24: SC | AG24: 96
A25: 82a54c5696f22a0615c5fe34f1830345 | B25: SP | C25: 45325 | D25: 45335 | E25: 45340 | F25: bed_bath_table | G25: 55.04 | H25: 14.16 | I25: boleto | J25: 5 | K25: delivered | L25: =DATE(YEAR(C25),MONTH(C25),1) -> 45323 | M25: =D25-C25 -> 10 | N25: =MAX(0,D25-E25) -> 0 | O25: =IF(D25<=E25,1,0) -> 1 | P25: =G25+H25 -> 69.2 | Q25: =G25*INDEX(Assumptions!$B$8:$B$16,MATCH(F25,Assumptions!$A$8:$A$16,0)) -> 34.1248 | R25: =H25*Assumptions!$B$3 -> 8.496 | S25: =G25-Q25-R25 -> 12.4192 | T25: =IF(M25<=7,"0-7 days",IF(M25<=14,"8-14 days",IF(M25<=21,"15-21 days","22+ days"))) -> 8-14 days | AF25: BA | AG25: 65
A26: 52fb86828f45dd4c9ed55243493c0253 | B26: SP | C26: 45325 | D26: 45336 | E26: 45337 | F26: furniture_decor | G26: 67.99 | H26: 12.43 | I26: credit_card | J26: 4 | K26: delivered | L26: =DATE(YEAR(C26),MONTH(C26),1) -> 45323 | M26: =D26-C26 -> 11 | N26: =MAX(0,D26-E26) -> 0 | O26: =IF(D26<=E26,1,0) -> 1 | P26: =G26+H26 -> 80.42 | Q26: =G26*INDEX(Assumptions!$B$8:$B$16,MATCH(F26,Assumptions!$A$8:$A$16,0)) -> 47.593 | R26: =H26*Assumptions!$B$3 -> 7.458 | S26: =G26-Q26-R26 -> 12.939 | T26: =IF(M26<=7,"0-7 days",IF(M26<=14,"8-14 days",IF(M26<=21,"15-21 days","22+ days"))) -> 8-14 days | AF26: GO | AG26: 60
A27: 3756b0058844bc0caccfb130e4872e77 | B27: SP | C27: 45326 | D27: 45332 | E27: 45341 | F27: watches_gifts | G27: 138.64 | H27: 20.77 | I27: credit_card | J27: 4 | K27: delivered | L27: =DATE(YEAR(C27),MONTH(C27),1) -> 45323 | M27: =D27-C27 -> 6 | N27: =MAX(0,D27-E27) -> 0 | O27: =IF(D27<=E27,1,0) -> 1 | P27: =G27+H27 -> 159.41 | Q27: =G27*INDEX(Assumptions!$B$8:$B$16,MATCH(F27,Assumptions!$A$8:$A$16,0)) -> 91.5024 | R27: =H27*Assumptions!$B$3 -> 12.462 | S27: =G27-Q27-R27 -> 34.6756 | T27: =IF(M27<=7,"0-7 days",IF(M27<=14,"8-14 days",IF(M27<=21,"15-21 days","22+ days"))) -> 0-7 days | AF27: DF | AG27: 52
A28: 1d5206abb7e6427cbf780e3ff6b751f7 | B28: SP | C28: 45327 | D28: 45333 | E28: 45346 | F28: furniture_decor | G28: 69.1 | H28: 18.24 | I28: boleto | J28: 5 | K28: delivered | L28: =DATE(YEAR(C28),MONTH(C28),1) -> 45323 | M28: =D28-C28 -> 6 | N28: =MAX(0,D28-E28) -> 0 | O28: =IF(D28<=E28,1,0) -> 1 | P28: =G28+H28 -> 87.34 | Q28: =G28*INDEX(Assumptions!$B$8:$B$16,MATCH(F28,Assumptions!$A$8:$A$16,0)) -> 48.37 | R28: =H28*Assumptions!$B$3 -> 10.944 | S28: =G28-Q28-R28 -> 9.786 | T28: =IF(M28<=7,"0-7 days",IF(M28<=14,"8-14 days",IF(M28<=21,"15-21 days","22+ days"))) -> 0-7 days | AF28: PE | AG28: 42
A29: 1d8709660710d430f071d87954c63cd8 | B29: SP | C29: 45329 | D29: 45336 | E29: 45348 | F29: sports_leisure | G29: 92.54 | H29: 21.21 | I29: boleto | J29: 5 | K29: delivered | L29: =DATE(YEAR(C29),MONTH(C29),1) -> 45323 | M29: =D29-C29 -> 7 | N29: =MAX(0,D29-E29) -> 0 | O29: =IF(D29<=E29,1,0) -> 1 | P29: =G29+H29 -> 113.75 | Q29: =G29*INDEX(Assumptions!$B$8:$B$16,MATCH(F29,Assumptions!$A$8:$A$16,0)) -> 59.2256 | R29: =H29*Assumptions!$B$3 -> 12.726 | S29: =G29-Q29-R29 -> 20.5884 | T29: =IF(M29<=7,"0-7 days",IF(M29<=14,"8-14 days",IF(M29<=21,"15-21 days","22+ days"))) -> 0-7 days | AF29: ES | AG29: 33
A30: 4291c441954ad961760a58a63d8ad67b | B30: RJ | C30: 45330 | D30: 45353 | E30: 45355 | F30: auto | G30: 146.52 | H30: 30.68 | I30: credit_card | J30: 3 | K30: delivered | L30: =DATE(YEAR(C30),MONTH(C30),1) -> 45323 | M30: =D30-C30 -> 23 | N30: =MAX(0,D30-E30) -> 0 | O30: =IF(D30<=E30,1,0) -> 1 | P30: =G30+H30 -> 177.2 | Q30: =G30*INDEX(Assumptions!$B$8:$B$16,MATCH(F30,Assumptions!$A$8:$A$16,0)) -> 99.6336 | R30: =H30*Assumptions!$B$3 -> 18.408 | S30: =G30-Q30-R30 -> 28.4784 | T30: =IF(M30<=7,"0-7 days",IF(M30<=14,"8-14 days",IF(M30<=21,"15-21 days","22+ days"))) -> 22+ days | AF30: CE | AG30: 25
A31: 06cb0fb39a1de644815ef6d13b8faa18 | B31: MG | C31: 45331 | D31: 45341 | E31: 45355 | F31: computers_accessories | G31: 114.08 | H31: 17.59 | I31: credit_card | J31: 5 | K31: delivered | L31: =DATE(YEAR(C31),MONTH(C31),1) -> 45323 | M31: =D31-C31 -> 10 | N31: =MAX(0,D31-E31) -> 0 | O31: =IF(D31<=E31,1,0) -> 1 | P31: =G31+H31 -> 131.67 | Q31: =G31*INDEX(Assumptions!$B$8:$B$16,MATCH(F31,Assumptions!$A$8:$A$16,0)) -> 84.4192 | R31: =H31*Assumptions!$B$3 -> 10.554 | S31: =G31-Q31-R31 -> 19.1068 | T31: =IF(M31<=7,"0-7 days",IF(M31<=14,"8-14 days",IF(M31<=21,"15-21 days","22+ days"))) -> 8-14 days | AF31: Grand Total | AG31: 2000
A32: a391ffdb8794ac7e4aaa7f994a34041e | B32: RS | C32: 45331 | D32: 45337 | E32: 45357 | F32: health_beauty | G32: 37.76 | H32: 21.64 | I32: voucher | J32: 5 | K32: delivered | L32: =DATE(YEAR(C32),MONTH(C32),1) -> 45323 | M32: =D32-C32 -> 6 | N32: =MAX(0,D32-E32) -> 0 | O32: =IF(D32<=E32,1,0) -> 1 | P32: =G32+H32 -> 59.4 | Q32: =G32*INDEX(Assumptions!$B$8:$B$16,MATCH(F32,Assumptions!$A$8:$A$16,0)) -> 21.9008 | R32: =H32*Assumptions!$B$3 -> 12.984 | S32: =G32-Q32-R32 -> 2.8752 | T32: =IF(M32<=7,"0-7 days",IF(M32<=14,"8-14 days",IF(M32<=21,"15-21 days","22+ days"))) -> 0-7 days
A33: e85cc86348cff1da7bbccb5d474f9205 | B33: RJ | C33: 45331 | D33: 45346 | E33: 45359 | F33: sports_leisure | G33: 76.03 | H33: 22.19 | I33: credit_card | J33: 4 | K33: delivered | L33: =DATE(YEAR(C33),MONTH(C33),1) -> 45323 | M33: =D33-C33 -> 15 | N33: =MAX(0,D33-E33) -> 0 | O33: =IF(D33<=E33,1,0) -> 1 | P33: =G33+H33 -> 98.22 | Q33: =G33*INDEX(Assumptions!$B$8:$B$16,MATCH(F33,Assumptions!$A$8:$A$16,0)) -> 48.6592 | R33: =H33*Assumptions!$B$3 -> 13.314 | S33: =G33-Q33-R33 -> 14.0568 | T33: =IF(M33<=7,"0-7 days",IF(M33<=14,"8-14 days",IF(M33<=21,"15-21 days","22+ days"))) -> 15-21 days
A34: 8ffbcc0f058729f37c03af356577aba9 | B34: BA | C34: 45331 | D34: 45353 | E34: 45360 | F34: auto | G34: 43.19 | H34: 32.82 | I34: credit_card | J34: 4 | K34: delivered | L34: =DATE(YEAR(C34),MONTH(C34),1) -> 45323 | M34: =D34-C34 -> 22 | N34: =MAX(0,D34-E34) -> 0 | O34: =IF(D34<=E34,1,0) -> 1 | P34: =G34+H34 -> 76.01 | Q34: =G34*INDEX(Assumptions!$B$8:$B$16,MATCH(F34,Assumptions!$A$8:$A$16,0)) -> 29.3692 | R34: =H34*Assumptions!$B$3 -> 19.692 | S34: =G34-Q34-R34 -> -5.8712 | T34: =IF(M34<=7,"0-7 days",IF(M34<=14,"8-14 days",IF(M34<=21,"15-21 days","22+ days"))) -> 22+ days
A35: dd357f0db0427c62ce9fb2785f942c43 | B35: SP | C35: 45332 | D35: 45341 | E35: 45346 | F35: computers_accessories | G35: 134.13 | H35: 16.76 | I35: credit_card | J35: 5 | K35: delivered | L35: =DATE(YEAR(C35),MONTH(C35),1) -> 45323 | M35: =D35-C35 -> 9 | N35: =MAX(0,D35-E35) -> 0 | O35: =IF(D35<=E35,1,0) -> 1 | P35: =G35+H35 -> 150.89 | Q35: =G35*INDEX(Assumptions!$B$8:$B$16,MATCH(F35,Assumptions!$A$8:$A$16,0)) -> 99.2562 | R35: =H35*Assumptions!$B$3 -> 10.056 | S35: =G35-Q35-R35 -> 24.8178 | T35: =IF(M35<=7,"0-7 days",IF(M35<=14,"8-14 days",IF(M35<=21,"15-21 days","22+ days"))) -> 8-14 days
A36: 950f5effdc5136e4d912d963d32a9e06 | B36: SP | C36: 45333 | D36: 45339 | E36: 45350 | F36: computers_accessories | G36: 142.46 | H36: 18.04 | I36: credit_card | J36: 3 | K36: delivered | L36: =DATE(YEAR(C36),MONTH(C36),1) -> 45323 | M36: =D36-C36 -> 6 | N36: =MAX(0,D36-E36) -> 0 | O36: =IF(D36<=E36,1,0) -> 1 | P36: =G36+H36 -> 160.5 | Q36: =G36*INDEX(Assumptions!$B$8:$B$16,MATCH(F36,Assumptions!$A$8:$A$16,0)) -> 105.4204 | R36: =H36*Assumptions!$B$3 -> 10.824 | S36: =G36-Q36-R36 -> 26.2156 | T36: =IF(M36<=7,"0-7 days",IF(M36<=14,"8-14 days",IF(M36<=21,"15-21 days","22+ days"))) -> 0-7 days
A37: 52dcbffd59008d658b2ab7592fc6c4e6 | B37: RS | C37: 45335 | D37: 45348 | E37: 45362 | F37: furniture_decor | G37: 57.74 | H37: 19.48 | I37: credit_card | J37: 4 | K37: delivered | L37: =DATE(YEAR(C37),MONTH(C37),1) -> 45323 | M37: =D37-C37 -> 13 | N37: =MAX(0,D37-E37) -> 0 | O37: =IF(D37<=E37,1,0) -> 1 | P37: =G37+H37 -> 77.22 | Q37: =G37*INDEX(Assumptions!$B$8:$B$16,MATCH(F37,Assumptions!$A$8:$A$16,0)) -> 40.418 | R37: =H37*Assumptions!$B$3 -> 11.688 | S37: =G37-Q37-R37 -> 5.634 | T37: =IF(M37<=7,"0-7 days",IF(M37<=14,"8-14 days",IF(M37<=21,"15-21 days","22+ days"))) -> 8-14 days
A38: 7eac652a78224ffa4027dfbdb1e37336 | B38: RS | C38: 45336 | D38: 45349 | E38: 45361 | F38: sports_leisure | G38: 83.82 | H38: 25.55 | I38: credit_card | J38: 5 | K38: delivered | L38: =DATE(YEAR(C38),MONTH(C38),1) -> 45323 | M38: =D38-C38 -> 13 | N38: =MAX(0,D38-E38) -> 0 | O38: =IF(D38<=E38,1,0) -> 1 | P38: =G38+H38 -> 109.37 | Q38: =G38*INDEX(Assumptions!$B$8:$B$16,MATCH(F38,Assumptions!$A$8:$A$16,0)) -> 53.6448 | R38: =H38*Assumptions!$B$3 -> 15.33 | S38: =G38-Q38-R38 -> 14.8452 | T38: =IF(M38<=7,"0-7 days",IF(M38<=14,"8-14 days",IF(M38<=21,"15-21 days","22+ days"))) -> 8-14 days
A39: ad1624e170a26ad8517b9145c48383a4 | B39: RS | C39: 45338 | D39: 45352 | E39: 45364 | F39: watches_gifts | G39: 105.36 | H39: 28 | I39: boleto | J39: 3 | K39: delivered | L39: =DATE(YEAR(C39),MONTH(C39),1) -> 45323 | M39: =D39-C39 -> 14 | N39: =MAX(0,D39-E39) -> 0 | O39: =IF(D39<=E39,1,0) -> 1 | P39: =G39+H39 -> 133.36 | Q39: =G39*INDEX(Assumptions!$B$8:$B$16,MATCH(F39,Assumptions!$A$8:$A$16,0)) -> 69.5376 | R39: =H39*Assumptions!$B$3 -> 16.8 | S39: =G39-Q39-R39 -> 19.0224 | T39: =IF(M39<=7,"0-7 days",IF(M39<=14,"8-14 days",IF(M39<=21,"15-21 days","22+ days"))) -> 8-14 days
A40: c09c2ebe80da2ed7880bcb0ec8ab96ac | B40: SP | C40: 45339 | D40: 45353 | E40: 45354 | F40: bed_bath_table | G40: 69.47 | H40: 12.3 | I40: credit_card | J40: 5 | K40: delivered | L40: =DATE(YEAR(C40),MONTH(C40),1) -> 45323 | M40: =D40-C40 -> 14 | N40: =MAX(0,D40-E40) -> 0 | O40: =IF(D40<=E40,1,0) -> 1 | P40: =G40+H40 -> 81.77 | Q40: =G40*INDEX(Assumptions!$B$8:$B$16,MATCH(F40,Assumptions!$A$8:$A$16,0)) -> 43.0714 | R40: =H40*Assumptions!$B$3 -> 7.38 | S40: =G40-Q40-R40 -> 19.0186 | T40: =IF(M40<=7,"0-7 days",IF(M40<=14,"8-14 days",IF(M40<=21,"15-21 days","22+ days"))) -> 8-14 days
...

Sheet Assumptions
A1: Assumptions & Notes
A3: Share of freight absorbed by the platform | B3: 0.6 | C3: Assumption (editable): Olist data has no cost data, so this is my modelling input.
A5: Cost of goods as % of price, by category (assumed)
A7: Category | B7: Cost Ratio
A8: bed_bath_table | B8: 0.62
A9: health_beauty | B9: 0.58
A10: sports_leisure | B10: 0.64
A11: furniture_decor | B11: 0.7
A12: computers_accessories | B12: 0.74
A13: watches_gifts | B13: 0.66
A14: housewares | B14: 0.63
A15: toys | B15: 0.6
A16: auto | B16: 0.68
A19: Legend: blue text / yellow fill = editable input. Change it and every sheet recalculates.
A21: Data note: this workbook uses a 2,000-order SAMPLE with the same column structure as the Olist Brazilian
A22: E-Commerce dataset (Kaggle). Replace the Data sheet (columns A-K) with real Olist rows and all formulas update.
A23: Profit = Price - COGS (price x category cost ratio) - absorbed freight (freight x absorb %).
A24: Only delivered orders are included.

Sheet State Analysis
A1: Sales & Delivery Analysis by State
A4: State | B4: Orders | C4: Order Share | D4: Revenue | E4: Net Profit | F4: Profit Margin | G4: Profit / Order | H4: Avg Order Value | I4: Avg Freight | J4: Avg Delivery Days | K4: On-Time % | L4: Volume Rank(No_of_order) | M4: Margin Rank(profit_margin) | N4: Rank Gap | O4: Insight Flag
A5: SP | B5: =COUNTIFS(Data!$B$2:$B$2001,A5) -> 909 | C5: =B5/$B$17 -> 0.4545 | D5: =SUMIFS(Data!$P$2:$P$2001,Data!$B$2:$B$2001,A5) -> 115617.11 | E5: =SUMIFS(Data!$S$2:$S$2001,Data!$B$2:$B$2001,A5) -> 25250.604 | F5: =IFERROR(E5/D5,0) -> 0.21839851 | G5: =IFERROR(E5/B5,0) -> 27.778443 | H5: =IFERROR(D5/B5,0) -> 127.19154 | I5: =IFERROR(AVERAGEIFS(Data!$H$2:$H$2001,Data!$B$2:$B$2001,A5),0) -> 17.822387 | J5: =IFERROR(AVERAGEIFS(Data!$M$2:$M$2001,Data!$B$2:$B$2001,A5),0) -> 8.6655666 | K5: =IFERROR(SUMIFS(Data!$O$2:$O$2001,Data!$B$2:$B$2001,A5)/B5,0) -> 0.94609461 | L5: =RANK(B5,$B$5:$B$16) -> 1 | M5: =RANK(F5,$F$5:$F$16) -> 1 | N5: =M5-L5 -> 0 | O5: =IF(AND(L5<=4,M5>=7),"High volume, low margin",IF(AND(L5>=7,M5<=4),"Low volume, high margin",""))
A6: RJ | B6: =COUNTIFS(Data!$B$2:$B$2001,A6) -> 252 | C6: =B6/$B$17 -> 0.126 | D6: =SUMIFS(Data!$P$2:$P$2001,Data!$B$2:$B$2001,A6) -> 32089.61 | E6: =SUMIFS(Data!$S$2:$S$2001,Data!$B$2:$B$2001,A6) -> 5451.465 | F6: =IFERROR(E6/D6,0) -> 0.16988256 | G6: =IFERROR(E6/B6,0) -> 21.632798 | H6: =IFERROR(D6/B6,0) -> 127.33972 | I6: =IFERROR(AVERAGEIFS(Data!$H$2:$H$2001,Data!$B$2:$B$2001,A6),0) -> 23.998294 | J6: =IFERROR(AVERAGEIFS(Data!$M$2:$M$2001,Data!$B$2:$B$2001,A6),0) -> 16.337302 | K6: =IFERROR(SUMIFS(Data!$O$2:$O$2001,Data!$B$2:$B$2001,A6)/B6,0) -> 0.90079365 | L6: =RANK(B6,$B$5:$B$16) -> 2 | M6: =RANK(F6,$F$5:$F$16) -> 8 | N6: =M6-L6 -> 6 | O6: =IF(AND(L6<=4,M6>=7),"High volume, low margin",IF(AND(L6>=7,M6<=4),"Low volume, high margin","")) -> High volume, low margin
A7: MG | B7: =COUNTIFS(Data!$B$2:$B$2001,A7) -> 241 | C7: =B7/$B$17 -> 0.1205 | D7: =SUMIFS(Data!$P$2:$P$2001,Data!$B$2:$B$2001,A7) -> 31045.7 | E7: =SUMIFS(Data!$S$2:$S$2001,Data!$B$2:$B$2001,A7) -> 5486.7233 | F7: =IFERROR(E7/D7,0) -> 0.17673054 | G7: =IFERROR(E7/B7,0) -> 22.766487 | H7: =IFERROR(D7/B7,0) -> 128.82033 | I7: =IFERROR(AVERAGEIFS(Data!$H$2:$H$2001,Data!$B$2:$B$2001,A7),0) -> 23.306349 | J7: =IFERROR(AVERAGEIFS(Data!$M$2:$M$2001,Data!$B$2:$B$2001,A7),0) -> 12.539419 | K7: =IFERROR(SUMIFS(Data!$O$2:$O$2001,Data!$B$2:$B$2001,A7)/B7,0) -> 0.95850622 | L7: =RANK(B7,$B$5:$B$16) -> 3 | M7: =RANK(F7,$F$5:$F$16) -> 6 | N7: =M7-L7 -> 3 | O7: =IF(AND(L7<=4,M7>=7),"High volume, low margin",IF(AND(L7>=7,M7<=4),"Low volume, high margin",""))
A8: RS | B8: =COUNTIFS(Data!$B$2:$B$2001,A8) -> 110 | C8: =B8/$B$17 -> 0.055 | D8: =SUMIFS(Data!$P$2:$P$2001,Data!$B$2:$B$2001,A8) -> 15610.33 | E8: =SUMIFS(Data!$S$2:$S$2001,Data!$B$2:$B$2001,A8) -> 2729.7099 | F8: =IFERROR(E8/D8,0) -> 0.17486561 | G8: =IFERROR(E8/B8,0) -> 24.815545 | H8: =IFERROR(D8/B8,0) -> 141.91209 | I8: =IFERROR(AVERAGEIFS(Data!$H$2:$H$2001,Data!$B$2:$B$2001,A8),0) -> 24.362 | J8: =IFERROR(AVERAGEIFS(Data!$M$2:$M$2001,Data!$B$2:$B$2001,A8),0) -> 16.372727 | K8: =IFERROR(SUMIFS(Data!$O$2:$O$2001,Data!$B$2:$B$2001,A8)/B8,0) -> 0.87272727 | L8: =RANK(B8,$B$5:$B$16) -> 5 | M8: =RANK(F8,$F$5:$F$16) -> 7 | N8: =M8-L8 -> 2 | O8: =IF(AND(L8<=4,M8>=7),"High volume, low margin",IF(AND(L8>=7,M8<=4),"Low volume, high margin",""))
A9: PR | B9: =COUNTIFS(Data!$B$2:$B$2001,A9) -> 115 | C9: =B9/$B$17 -> 0.0575 | D9: =SUMIFS(Data!$P$2:$P$2001,Data!$B$2:$B$2001,A9) -> 16873.04 | E9: =SUMIFS(Data!$S$2:$S$2001,Data!$B$2:$B$2001,A9) -> 3163.2744 | F9: =IFERROR(E9/D9,0) -> 0.18747507 | G9: =IFERROR(E9/B9,0) -> 27.506734 | H9: =IFERROR(D9/B9,0) -> 146.72209 | I9: =IFERROR(AVERAGEIFS(Data!$H$2:$H$2001,Data!$B$2:$B$2001,A9),0) -> 23.454522 | J9: =IFERROR(AVERAGEIFS(Data!$M$2:$M$2001,Data!$B$2:$B$2001,A9),0) -> 13.165217 | K9: =IFERROR(SUMIFS(Data!$O$2:$O$2001,Data!$B$2:$B$2001,A9)/B9,0) -> 0.88695652 | L9: =RANK(B9,$B$5:$B$16) -> 4 | M9: =RANK(F9,$F$5:$F$16) -> 4 | N9: =M9-L9 -> 0 | O9: =IF(AND(L9<=4,M9>=7),"High volume, low margin",IF(AND(L9>=7,M9<=4),"Low volume, high margin",""))
A10: SC | B10: =COUNTIFS(Data!$B$2:$B$2001,A10) -> 96 | C10: =B10/$B$17 -> 0.048 | D10: =SUMIFS(Data!$P$2:$P$2001,Data!$B$2:$B$2001,A10) -> 13452.91 | E10: =SUMIFS(Data!$S$2:$S$2001,Data!$B$2:$B$2001,A10) -> 2562.6194 | F10: =IFERROR(E10/D10,0) -> 0.19048811 | G10: =IFERROR(E10/B10,0) -> 26.693952 | H10: =IFERROR(D10/B10,0) -> 140.13448 | I10: =IFERROR(AVERAGEIFS(Data!$H$2:$H$2001,Data!$B$2:$B$2001,A10),0) -> 24.139896 | J10: =IFERROR(AVERAGEIFS(Data!$M$2:$M$2001,Data!$B$2:$B$2001,A10),0) -> 14.791667 | K10: =IFERROR(SUMIFS(Data!$O$2:$O$2001,Data!$B$2:$B$2001,A10)/B10,0) -> 0.92708333 | L10: =RANK(B10,$B$5:$B$16) -> 6 | M10: =RANK(F10,$F$5:$F$16) -> 3 | N10: =M10-L10 -> -3 | O10: =IF(AND(L10<=4,M10>=7),"High volume, low margin",IF(AND(L10>=7,M10<=4),"Low volume, high margin",""))
A11: BA | B11: =COUNTIFS(Data!$B$2:$B$2001,A11) -> 65 | C11: =B11/$B$17 -> 0.0325 | D11: =SUMIFS(Data!$P$2:$P$2001,Data!$B$2:$B$2001,A11) -> 8267.86 | E11: =SUMIFS(Data!$S$2:$S$2001,Data!$B$2:$B$2001,A11) -> 937.0956 | F11: =IFERROR(E11/D11,0) -> 0.11334198 | G11: =IFERROR(E11/B11,0) -> 14.416855 | H11: =IFERROR(D11/B11,0) -> 127.19785 | I11: =IFERROR(AVERAGEIFS(Data!$H$2:$H$2001,Data!$B$2:$B$2001,A11),0) -> 32.066308 | J11: =IFERROR(AVERAGEIFS(Data!$M$2:$M$2001,Data!$B$2:$B$2001,A11),0) -> 20.246154 | K11: =IFERROR(SUMIFS(Data!$O$2:$O$2001,Data!$B$2:$B$2001,A11)/B11,0) -> 0.93846154 | L11: =RANK(B11,$B$5:$B$16) -> 7 | M11: =RANK(F11,$F$5:$F$16) -> 12 | N11: =M11-L11 -> 5 | O11: =IF(AND(L11<=4,M11>=7),"High volume, low margin",IF(AND(L11>=7,M11<=4),"Low volume, high margin",""))
A12: DF | B12: =COUNTIFS(Data!$B$2:$B$2001,A12) -> 52 | C12: =B12/$B$17 -> 0.026 | D12: =SUMIFS(Data!$P$2:$P$2001,Data!$B$2:$B$2001,A12) -> 7697.46 | E12: =SUMIFS(Data!$S$2:$S$2001,Data!$B$2:$B$2001,A12) -> 1537.265 | F12: =IFERROR(E12/D12,0) -> 0.19971068 | G12: =IFERROR(E12/B12,0) -> 29.562788 | H12: =IFERROR(D12/B12,0) -> 148.02808 | I12: =IFERROR(AVERAGEIFS(Data!$H$2:$H$2001,Data!$B$2:$B$2001,A12),0) -> 24.015769 | J12: =IFERROR(AVERAGEIFS(Data!$M$2:$M$2001,Data!$B$2:$B$2001,A12),0) -> 13.673077 | K12: =IFERROR(SUMIFS(Data!$O$2:$O$2001,Data!$B$2:$B$2001,A12)/B12,0) -> 0.96153846 | L12: =RANK(B12,$B$5:$B$16) -> 9 | M12: =RANK(F12,$F$5:$F$16) -> 2 | N12: =M12-L12 -> -7 | O12: =IF(AND(L12<=4,M12>=7),"High volume, low margin",IF(AND(L12>=7,M12<=4),"Low volume, high margin","")) -> Low volume, high margin
A13: GO | B13: =COUNTIFS(Data!$B$2:$B$2001,A13) -> 60 | C13: =B13/$B$17 -> 0.03 | D13: =SUMIFS(Data!$P$2:$P$2001,Data!$B$2:$B$2001,A13) -> 9527.25 | E13: =SUMIFS(Data!$S$2:$S$2001,Data!$B$2:$B$2001,A13) -> 1708.0977 | F13: =IFERROR(E13/D13,0) -> 0.17928549 | G13: =IFERROR(E13/B13,0) -> 28.468295 | H13: =IFERROR(D13/B13,0) -> 158.7875 | I13: =IFERROR(AVERAGEIFS(Data!$H$2:$H$2001,Data!$B$2:$B$2001,A13),0) -> 26.811667 | J13: =IFERROR(AVERAGEIFS(Data!$M$2:$M$2001,Data!$B$2:$B$2001,A13),0) -> 17.7 | K13: =IFERROR(SUMIFS(Data!$O$2:$O$2001,Data!$B$2:$B$2001,A13)/B13,0) -> 0.81666667 | L13: =RANK(B13,$B$5:$B$16) -> 8 | M13: =RANK(F13,$F$5:$F$16) -> 5 | N13: =M13-L13 -> -3 | O13: =IF(AND(L13<=4,M13>=7),"High volume, low margin",IF(AND(L13>=7,M13<=4),"Low volume, high margin",""))
A14: ES | B14: =COUNTIFS(Data!$B$2:$B$2001,A14) -> 33 | C14: =B14/$B$17 -> 0.0165 | D14: =SUMIFS(Data!$P$2:$P$2001,Data!$B$2:$B$2001,A14) -> 4059.07 | E14: =SUMIFS(Data!$S$2:$S$2001,Data!$B$2:$B$2001,A14) -> 680.598 | F14: =IFERROR(E14/D14,0) -> 0.16767338 | G14: =IFERROR(E14/B14,0) -> 20.624182 | H14: =IFERROR(D14/B14,0) -> 123.00212 | I14: =IFERROR(AVERAGEIFS(Data!$H$2:$H$2001,Data!$B$2:$B$2001,A14),0) -> 25.128182 | J14: =IFERROR(AVERAGEIFS(Data!$M$2:$M$2001,Data!$B$2:$B$2001,A14),0) -> 15.969697 | K14: =IFERROR(SUMIFS(Data!$O$2:$O$2001,Data!$B$2:$B$2001,A14)/B14,0) -> 0.84848485 | L14: =RANK(B14,$B$5:$B$16) -> 11 | M14: =RANK(F14,$F$5:$F$16) -> 9 | N14: =M14-L14 -> -2 | O14: =IF(AND(L14<=4,M14>=7),"High volume, low margin",IF(AND(L14>=7,M14<=4),"Low volume, high margin",""))
A15: PE | B15: =COUNTIFS(Data!$B$2:$B$2001,A15) -> 42 | C15: =B15/$B$17 -> 0.021 | D15: =SUMIFS(Data!$P$2:$P$2001,Data!$B$2:$B$2001,A15) -> 6527.81 | E15: =SUMIFS(Data!$S$2:$S$2001,Data!$B$2:$B$2001,A15) -> 787.2045 | F15: =IFERROR(E15/D15,0) -> 0.12059243 | G15: =IFERROR(E15/B15,0) -> 18.742964 | H15: =IFERROR(D15/B15,0) -> 155.42405 | I15: =IFERROR(AVERAGEIFS(Data!$H$2:$H$2001,Data!$B$2:$B$2001,A15),0) -> 37.270714 | J15: =IFERROR(AVERAGEIFS(Data!$M$2:$M$2001,Data!$B$2:$B$2001,A15),0) -> 23.5 | K15: =IFERROR(SUMIFS(Data!$O$2:$O$2001,Data!$B$2:$B$2001,A15)/B15,0) -> 0.9047619 | L15: =RANK(B15,$B$5:$B$16) -> 10 | M15: =RANK(F15,$F$5:$F$16) -> 11 | N15: =M15-L15 -> 1 | O15: =IF(AND(L15<=4,M15>=7),"High volume, low margin",IF(AND(L15>=7,M15<=4),"Low volume, high margin",""))
A16: CE | B16: =COUNTIFS(Data!$B$2:$B$2001,A16) -> 25 | C16: =B16/$B$17 -> 0.0125 | D16: =SUMIFS(Data!$P$2:$P$2001,Data!$B$2:$B$2001,A16) -> 4157.51 | E16: =SUMIFS(Data!$S$2:$S$2001,Data!$B$2:$B$2001,A16) -> 561.9106 | F16: =IFERROR(E16/D16,0) -> 0.13515556 | G16: =IFERROR(E16/B16,0) -> 22.476424 | H16: =IFERROR(D16/B16,0) -> 166.3004 | I16: =IFERROR(AVERAGEIFS(Data!$H$2:$H$2001,Data!$B$2:$B$2001,A16),0) -> 40.014 | J16: =IFERROR(AVERAGEIFS(Data!$M$2:$M$2001,Data!$B$2:$B$2001,A16),0) -> 22.4 | K16: =IFERROR(SUMIFS(Data!$O$2:$O$2001,Data!$B$2:$B$2001,A16)/B16,0) -> 0.96 | L16: =RANK(B16,$B$5:$B$16) -> 12 | M16: =RANK(F16,$F$5:$F$16) -> 10 | N16: =M16-L16 -> -2 | O16: =IF(AND(L16<=4,M16>=7),"High volume, low margin",IF(AND(L16>=7,M16<=4),"Low volume, high margin",""))
A17: Total / Avg | B17: =SUM(B5:B16) -> 2000 | C17: =SUM(C5:C16) -> 1 | D17: =SUM(D5:D16) -> 264925.66 | E17: =SUM(E5:E16) -> 50856.568 | F17: =E17/D17 -> 0.19196543 | G17: =E17/B17 -> 25.428284 | H17: =D17/B17 -> 132.46283 | I17: =AVERAGE(Data!$H$2:$H$2001) -> 21.948125 | J17: =AVERAGE(Data!$M$2:$M$2001) -> 12.457 | K17: =SUM(Data!$O$2:$O$2001)/B17 -> 0.9275
A19: Rank Gap = Margin Rank - Volume Rank. A large positive gap means high order volume but weak profitability.
A22: order share =that_state_order/totoal order (from all order how much this state contribute)
A25: revenue_generate_by that state=use_sumif()
A28: net profit=Net Profit is the amount of money a business has left after subtracting all its expenses from its revenue
A32: net margin=net_profit/revenue*100 profit_margin=proft/revenue*100 eg 5000 revenue 1000 expenses 4000 is the profit
A36: Profit per Order = Net Profit ÷ Number of Orders It tells you, on average, how much net profit the business earns from each order.
A40: avg=total_revuew/toal_orders suahc as 3000=revenue/3=tifin_orders=avg=1000 is the avg order value
A43: freight=the_delivery_chargers_customer_pays freights_absorbed=delivery_charges_paid_by_the company

Sheet Monthly Trend
A1: Monthly Sales Trend
A2: Month list uses EDATE; moving average, MoM growth and cumulative revenue are formulas.
A4: Month | B4: Orders | C4: Revenue | D4: Net Profit | E4: Profit Margin | F4: MoM Order Growth | G4: 3-Mo Moving Avg Orders | H4: Cumulative Revenue | I4: Avg Delivery Days | J4: Flag
A5: 45292 | B5: =COUNTIFS(Data!$L$2:$L$2001,A5) -> 19 | C5: =SUMIFS(Data!$P$2:$P$2001,Data!$L$2:$L$2001,A5) -> 2172.54 | D5: =SUMIFS(Data!$S$2:$S$2001,Data!$L$2:$L$2001,A5) -> 430.0502 | E5: =IFERROR(D5/C5,0) -> 0.19794812 | F5: ="" | G5: ="" | H5: =SUM($C$5:C5) -> 2172.54 | I5: =IFERROR(AVERAGEIFS(Data!$M$2:$M$2001,Data!$L$2:$L$2001,A5),0) -> 12.315789 | J5: =IF(B5=MAX($B$5:$B$24),"Peak month",IF(B5=MIN($B$5:$B$24),"Lowest month","")) -> Lowest month
A6: =EDATE(A5,1) -> 45323 | B6: =COUNTIFS(Data!$L$2:$L$2001,A6) -> 32 | C6: =SUMIFS(Data!$P$2:$P$2001,Data!$L$2:$L$2001,A6) -> 3758.18 | D6: =SUMIFS(Data!$S$2:$S$2001,Data!$L$2:$L$2001,A6) -> 625.6623 | E6: =IFERROR(D6/C6,0) -> 0.16648013 | F6: =IFERROR(B6/B5-1,"") -> 0.68421053 | G6: ="" | H6: =SUM($C$5:C6) -> 5930.72 | I6: =IFERROR(AVERAGEIFS(Data!$M$2:$M$2001,Data!$L$2:$L$2001,A6),0) -> 12.03125 | J6: =IF(B6=MAX($B$5:$B$24),"Peak month",IF(B6=MIN($B$5:$B$24),"Lowest month",""))
A7: =EDATE(A6,1) -> 45352 | B7: =COUNTIFS(Data!$L$2:$L$2001,A7) -> 23 | C7: =SUMIFS(Data!$P$2:$P$2001,Data!$L$2:$L$2001,A7) -> 2771.36 | D7: =SUMIFS(Data!$S$2:$S$2001,Data!$L$2:$L$2001,A7) -> 497.0758 | E7: =IFERROR(D7/C7,0) -> 0.17936169 | F7: =IFERROR(B7/B6-1,"") -> -0.28125 | G7: =AVERAGE(B5:B7) -> 24.666667 | H7: =SUM($C$5:C7) -> 8702.08 | I7: =IFERROR(AVERAGEIFS(Data!$M$2:$M$2001,Data!$L$2:$L$2001,A7),0) -> 11.652174 | J7: =IF(B7=MAX($B$5:$B$24),"Peak month",IF(B7=MIN($B$5:$B$24),"Lowest month",""))
A8: =EDATE(A7,1) -> 45383 | B8: =COUNTIFS(Data!$L$2:$L$2001,A8) -> 50 | C8: =SUMIFS(Data!$P$2:$P$2001,Data!$L$2:$L$2001,A8) -> 6716.63 | D8: =SUMIFS(Data!$S$2:$S$2001,Data!$L$2:$L$2001,A8) -> 1223.0632 | E8: =IFERROR(D8/C8,0) -> 0.18209477 | F8: =IFERROR(B8/B7-1,"") -> 1.173913 | G8: =AVERAGE(B6:B8) -> 35 | H8: =SUM($C$5:C8) -> 15418.71 | I8: =IFERROR(AVERAGEIFS(Data!$M$2:$M$2001,Data!$L$2:$L$2001,A8),0) -> 12.06 | J8: =IF(B8=MAX($B$5:$B$24),"Peak month",IF(B8=MIN($B$5:$B$24),"Lowest month",""))
A9: =EDATE(A8,1) -> 45413 | B9: =COUNTIFS(Data!$L$2:$L$2001,A9) -> 50 | C9: =SUMIFS(Data!$P$2:$P$2001,Data!$L$2:$L$2001,A9) -> 6607.42 | D9: =SUMIFS(Data!$S$2:$S$2001,Data!$L$2:$L$2001,A9) -> 1236.3609 | E9: =IFERROR(D9/C9,0) -> 0.18711704 | F9: =IFERROR(B9/B8-1,"") -> 0 | G9: =AVERAGE(B7:B9) -> 41 | H9: =SUM($C$5:C9) -> 22026.13 | I9: =IFERROR(AVERAGEIFS(Data!$M$2:$M$2001,Data!$L$2:$L$2001,A9),0) -> 14.08 | J9: =IF(B9=MAX($B$5:$B$24),"Peak month",IF(B9=MIN($B$5:$B$24),"Lowest month",""))
A10: =EDATE(A9,1) -> 45444 | B10: =COUNTIFS(Data!$L$2:$L$2001,A10) -> 62 | C10: =SUMIFS(Data!$P$2:$P$2001,Data!$L$2:$L$2001,A10) -> 7950.55 | D10: =SUMIFS(Data!$S$2:$S$2001,Data!$L$2:$L$2001,A10) -> 1494.4801 | E10: =IFERROR(D10/C10,0) -> 0.18797191 | F10: =IFERROR(B10/B9-1,"") -> 0.24 | G10: =AVERAGE(B8:B10) -> 54 | H10: =SUM($C$5:C10) -> 29976.68 | I10: =IFERROR(AVERAGEIFS(Data!$M$2:$M$2001,Data!$L$2:$L$2001,A10),0) -> 11.741935 | J10: =IF(B10=MAX($B$5:$B$24),"Peak month",IF(B10=MIN($B$5:$B$24),"Lowest month",""))
A11: =EDATE(A10,1) -> 45474 | B11: =COUNTIFS(Data!$L$2:$L$2001,A11) -> 86 | C11: =SUMIFS(Data!$P$2:$P$2001,Data!$L$2:$L$2001,A11) -> 11224.26 | D11: =SUMIFS(Data!$S$2:$S$2001,Data!$L$2:$L$2001,A11) -> 2302.3632 | E11: =IFERROR(D11/C11,0) -> 0.20512383 | F11: =IFERROR(B11/B10-1,"") -> 0.38709677 | G11: =AVERAGE(B9:B11) -> 66 | H11: =SUM($C$5:C11) -> 41200.94 | I11: =IFERROR(AVERAGEIFS(Data!$M$2:$M$2001,Data!$L$2:$L$2001,A11),0) -> 12.44186 | J11: =IF(B11=MAX($B$5:$B$24),"Peak month",IF(B11=MIN($B$5:$B$24),"Lowest month",""))
A12: =EDATE(A11,1) -> 45505 | B12: =COUNTIFS(Data!$L$2:$L$2001,A12) -> 94 | C12: =SUMIFS(Data!$P$2:$P$2001,Data!$L$2:$L$2001,A12) -> 11209.59 | D12: =SUMIFS(Data!$S$2:$S$2001,Data!$L$2:$L$2001,A12) -> 1998.6299 | E12: =IFERROR(D12/C12,0) -> 0.17829643 | F12: =IFERROR(B12/B11-1,"") -> 0.093023256 | G12: =AVERAGE(B10:B12) -> 80.666667 | H12: =SUM($C$5:C12) -> 52410.53 | I12: =IFERROR(AVERAGEIFS(Data!$M$2:$M$2001,Data!$L$2:$L$2001,A12),0) -> 11.851064 | J12: =IF(B12=MAX($B$5:$B$24),"Peak month",IF(B12=MIN($B$5:$B$24),"Lowest month",""))
A13: =EDATE(A12,1) -> 45536 | B13: =COUNTIFS(Data!$L$2:$L$2001,A13) -> 76 | C13: =SUMIFS(Data!$P$2:$P$2001,Data!$L$2:$L$2001,A13) -> 9815 | D13: =SUMIFS(Data!$S$2:$S$2001,Data!$L$2:$L$2001,A13) -> 1868.7309 | E13: =IFERROR(D13/C13,0) -> 0.1903954 | F13: =IFERROR(B13/B12-1,"") -> -0.19148936 | G13: =AVERAGE(B11:B13) -> 85.333333 | H13: =SUM($C$5:C13) -> 62225.53 | I13: =IFERROR(AVERAGEIFS(Data!$M$2:$M$2001,Data!$L$2:$L$2001,A13),0) -> 13.052632 | J13: =IF(B13=MAX($B$5:$B$24),"Peak month",IF(B13=MIN($B$5:$B$24),"Lowest month",""))
A14: =EDATE(A13,1) -> 45566 | B14: =COUNTIFS(Data!$L$2:$L$2001,A14) -> 93 | C14: =SUMIFS(Data!$P$2:$P$2001,Data!$L$2:$L$2001,A14) -> 12961.28 | D14: =SUMIFS(Data!$S$2:$S$2001,Data!$L$2:$L$2001,A14) -> 2459.5793 | E14: =IFERROR(D14/C14,0) -> 0.18976361 | F14: =IFERROR(B14/B13-1,"") -> 0.22368421 | G14: =AVERAGE(B12:B14) -> 87.666667 | H14: =SUM($C$5:C14) -> 75186.81 | I14: =IFERROR(AVERAGEIFS(Data!$M$2:$M$2001,Data!$L$2:$L$2001,A14),0) -> 13.483871 | J14: =IF(B14=MAX($B$5:$B$24),"Peak month",IF(B14=MIN($B$5:$B$24),"Lowest month",""))
A15: =EDATE(A14,1) -> 45597 | B15: =COUNTIFS(Data!$L$2:$L$2001,A15) -> 162 | C15: =SUMIFS(Data!$P$2:$P$2001,Data!$L$2:$L$2001,A15) -> 22385.65 | D15: =SUMIFS(Data!$S$2:$S$2001,Data!$L$2:$L$2001,A15) -> 4342.0319 | E15: =IFERROR(D15/C15,0) -> 0.19396497 | F15: =IFERROR(B15/B14-1,"") -> 0.74193548 | G15: =AVERAGE(B13:B15) -> 110.33333 | H15: =SUM($C$5:C15) -> 97572.46 | I15: =IFERROR(AVERAGEIFS(Data!$M$2:$M$2001,Data!$L$2:$L$2001,A15),0) -> 12.246914 | J15: =IF(B15=MAX($B$5:$B$24),"Peak month",IF(B15=MIN($B$5:$B$24),"Lowest month",""))
A16: =EDATE(A15,1) -> 45627 | B16: =COUNTIFS(Data!$L$2:$L$2001,A16) -> 130 | C16: =SUMIFS(Data!$P$2:$P$2001,Data!$L$2:$L$2001,A16) -> 17841.41 | D16: =SUMIFS(Data!$S$2:$S$2001,Data!$L$2:$L$2001,A16) -> 3479.1945 | E16: =IFERROR(D16/C16,0) -> 0.1950067 | F16: =IFERROR(B16/B15-1,"") -> -0.19753086 | G16: =AVERAGE(B14:B16) -> 128.33333 | H16: =SUM($C$5:C16) -> 115413.87 | I16: =IFERROR(AVERAGEIFS(Data!$M$2:$M$2001,Data!$L$2:$L$2001,A16),0) -> 13.284615 | J16: =IF(B16=MAX($B$5:$B$24),"Peak month",IF(B16=MIN($B$5:$B$24),"Lowest month",""))
A17: =EDATE(A16,1) -> 45658 | B17: =COUNTIFS(Data!$L$2:$L$2001,A17) -> 110 | C17: =SUMIFS(Data!$P$2:$P$2001,Data!$L$2:$L$2001,A17) -> 14582.56 | D17: =SUMIFS(Data!$S$2:$S$2001,Data!$L$2:$L$2001,A17) -> 2686.1614 | E17: =IFERROR(D17/C17,0) -> 0.18420369 | F17: =IFERROR(B17/B16-1,"") -> -0.15384615 | G17: =AVERAGE(B15:B17) -> 134 | H17: =SUM($C$5:C17) -> 129996.43 | I17: =IFERROR(AVERAGEIFS(Data!$M$2:$M$2001,Data!$L$2:$L$2001,A17),0) -> 12.136364 | J17: =IF(B17=MAX($B$5:$B$24),"Peak month",IF(B17=MIN($B$5:$B$24),"Lowest month",""))
A18: =EDATE(A17,1) -> 45689 | B18: =COUNTIFS(Data!$L$2:$L$2001,A18) -> 118 | C18: =SUMIFS(Data!$P$2:$P$2001,Data!$L$2:$L$2001,A18) -> 15315.65 | D18: =SUMIFS(Data!$S$2:$S$2001,Data!$L$2:$L$2001,A18) -> 2961.8738 | E18: =IFERROR(D18/C18,0) -> 0.19338871 | F18: =IFERROR(B18/B17-1,"") -> 0.072727273 | G18: =AVERAGE(B16:B18) -> 119.33333 | H18: =SUM($C$5:C18) -> 145312.08 | I18: =IFERROR(AVERAGEIFS(Data!$M$2:$M$2001,Data!$L$2:$L$2001,A18),0) -> 12.237288 | J18: =IF(B18=MAX($B$5:$B$24),"Peak month",IF(B18=MIN($B$5:$B$24),"Lowest month",""))
... A24: =EDATE(A23,1) -> 45870 | B24: =COUNTIFS(Data!$L$2:$L$2001,A24) -> 188 | C24: =SUMIFS(Data!$P$2:$P$2001,Data!$L$2:$L$2001,A24) -> 25620.95 | D24: =SUMIFS(Data!$S$2:$S$2001,Data!$L$2:$L$2001,A24) -> 5071.6196 | E24: =IFERROR(D24/C24,0) -> 0.19794815 | F24: =IFERROR(B24/B23-1,"") -> 0.21290323 | G24: =AVERAGE(B22:B24) -> 167.33333 | H24: =SUM($C$5:C24) -> 264925.66 | I24: =IFERROR(AVERAGEIFS(Data!$M$2:$M$2001,Data!$L$2:$L$2001,A24),0) -> 12.090426 | J24: =IF(B24=MAX($B$5:$B$24),"Peak month",IF(B24=MIN($B$5:$B$24),"Lowest month","")) -> Peak month

Sheet Delivery Analysis
A1: Delivery Performance Analysis
A2: Section 1: delivery-time buckets. Section 2: on-time vs late. Section 3: bottleneck states.
A4: Delivery Time Bucket | B4: Orders | C4: Share of Orders | D4: Avg Review Score | E4: Avg Profit / Order | F4: Late %
A5: 0-7 days | B5: =COUNTIFS(Data!$T$2:$T$2001,A5) -> 467 | C5: =B5/SUM($B$5:$B$8) -> 0.2335 | D5: =IFERROR(AVERAGEIFS(Data!$J$2:$J$2001,Data!$T$2:$T$2001,A5),0) -> 4.4218415 | E5: =IFERROR(AVERAGEIFS(Data!$S$2:$S$2001,Data!$T$2:$T$2001,A5),0) -> 24.822757 | F5: =IFERROR(1-SUMIFS(Data!$O$2:$O$2001,Data!$T$2:$T$2001,A5)/B5,0) -> 0
A6: 8-14 days | B6: =COUNTIFS(Data!$T$2:$T$2001,A6) -> 950 | C6: =B6/SUM($B$5:$B$8) -> 0.475 | D6: =IFERROR(AVERAGEIFS(Data!$J$2:$J$2001,Data!$T$2:$T$2001,A6),0) -> 4.3884211 | E6: =IFERROR(AVERAGEIFS(Data!$S$2:$S$2001,Data!$T$2:$T$2001,A6),0) -> 26.402889 | F6: =IFERROR(1-SUMIFS(Data!$O$2:$O$2001,Data!$T$2:$T$2001,A6)/B6,0) -> 0.013684211
A7: 15-21 days | B7: =COUNTIFS(Data!$T$2:$T$2001,A7) -> 403 | C7: =B7/SUM($B$5:$B$8) -> 0.2015 | D7: =IFERROR(AVERAGEIFS(Data!$J$2:$J$2001,Data!$T$2:$T$2001,A7),0) -> 4.0421836 | E7: =IFERROR(AVERAGEIFS(Data!$S$2:$S$2001,Data!$T$2:$T$2001,A7),0) -> 23.769244 | F7: =IFERROR(1-SUMIFS(Data!$O$2:$O$2001,Data!$T$2:$T$2001,A7)/B7,0) -> 0.089330025
A8: 22+ days | B8: =COUNTIFS(Data!$T$2:$T$2001,A8) -> 180 | C8: =B8/SUM($B$5:$B$8) -> 0.09 | D8: =IFERROR(AVERAGEIFS(Data!$J$2:$J$2001,Data!$T$2:$T$2001,A8),0) -> 3.1444444 | E8: =IFERROR(AVERAGEIFS(Data!$S$2:$S$2001,Data!$T$2:$T$2001,A8),0) -> 25.569946 | F8: =IFERROR(1-SUMIFS(Data!$O$2:$O$2001,Data!$T$2:$T$2001,A8)/B8,0) -> 0.53333333
A11: Delivery Status | B11: Orders | C11: Share of Orders | D11: Avg Review Score | E11: Avg Profit / Order | F11: Avg Delay (days)
A12: On-time | B12: =COUNTIFS(Data!$O$2:$O$2001,1) -> 1855 | C12: =B12/SUM($B$12:$B$13) -> 0.9275 | D12: =IFERROR(AVERAGEIFS(Data!$J$2:$J$2001,Data!$O$2:$O$2001,1),0) -> 4.3358491 | E12: =IFERROR(AVERAGEIFS(Data!$S$2:$S$2001,Data!$O$2:$O$2001,1),0) -> 25.217932 | F12: =IFERROR(AVERAGEIFS(Data!$N$2:$N$2001,Data!$O$2:$O$2001,1),0) -> 0
A13: Late | B13: =COUNTIFS(Data!$O$2:$O$2001,0) -> 145 | C13: =B13/SUM($B$12:$B$13) -> 0.0725 | D13: =IFERROR(AVERAGEIFS(Data!$J$2:$J$2001,Data!$O$2:$O$2001,0),0) -> 2.662069 | E13: =IFERROR(AVERAGEIFS(Data!$S$2:$S$2001,Data!$O$2:$O$2001,0),0) -> 28.119342 | F13: =IFERROR(AVERAGEIFS(Data!$N$2:$N$2001,Data!$O$2:$O$2001,0),0) -> 4.8896552
A14: Review score drop when late | D14: =D12-D13 -> 1.6737801
A17: State | B17: Avg Delivery Days | C17: On-Time % | D17: Avg Delay of Late Orders | E17: Avg Review Score | F17: Bottleneck Rating
A18: SP | B18: =IFERROR(AVERAGEIFS(Data!$M$2:$M$2001,Data!$B$2:$B$2001,A18),0) -> 8.6655666 | C18: =IFERROR(SUMIFS(Data!$O$2:$O$2001,Data!$B$2:$B$2001,A18)/COUNTIFS(Data!$B$2:$B$2001,A18),0) -> 0.94609461 | D18: =IFERROR(AVERAGEIFS(Data!$N$2:$N$2001,Data!$B$2:$B$2001,A18,Data!$O$2:$O$2001,0),0) -> 3.4285714 | E18: =IFERROR(AVERAGEIFS(Data!$J$2:$J$2001,Data!$B$2:$B$2001,A18),0) -> 4.3421342 | F18: =IF(B18>=$B$30*1.25,"High",IF(B18>=$B$30,"Medium","Low")) -> Low
A19: RJ | B19: =IFERROR(AVERAGEIFS(Data!$M$2:$M$2001,Data!$B$2:$B$2001,A19),0) -> 16.337302 | C19: =IFERROR(SUMIFS(Data!$O$2:$O$2001,Data!$B$2:$B$2001,A19)/COUNTIFS(Data!$B$2:$B$2001,A19),0) -> 0.90079365 | D19: =IFERROR(AVERAGEIFS(Data!$N$2:$N$2001,Data!$B$2:$B$2001,A19,Data!$O$2:$O$2001,0),0) -> 5.88 | E19: =IFERROR(AVERAGEIFS(Data!$J$2:$J$2001,Data!$B$2:$B$2001,A19),0) -> 4.0079365 | F19: =IF(B19>=$B$30*1.25,"High",IF(B19>=$B$30,"Medium","Low")) -> High
A20: MG | B20: =IFERROR(AVERAGEIFS(Data!$M$2:$M$2001,Data!$B$2:$B$2001,A20),0) -> 12.539419 | C20: =IFERROR(SUMIFS(Data!$O$2:$O$2001,Data!$B$2:$B$2001,A20)/COUNTIFS(Data!$B$2:$B$2001,A20),0) -> 0.95850622 | D20: =IFERROR(AVERAGEIFS(Data!$N$2:$N$2001,Data!$B$2:$B$2001,A20,Data!$O$2:$O$2001,0),0) -> 4.4 | E20: =IFERROR(AVERAGEIFS(Data!$J$2:$J$2001,Data!$B$2:$B$2001,A20),0) -> 4.3526971 | F20: =IF(B20>=$B$30*1.25,"High",IF(B20>=$B$30,"Medium","Low")) -> Medium
A21: RS | B21: =IFERROR(AVERAGEIFS(Data!$M$2:$M$2001,Data!$B$2:$B$2001,A21),0) -> 16.372727 | C21: =IFERROR(SUMIFS(Data!$O$2:$O$2001,Data!$B$2:$B$2001,A21)/COUNTIFS(Data!$B$2:$B$2001,A21),0) -> 0.87272727 | D21: =IFERROR(AVERAGEIFS(Data!$N$2:$N$2001,Data!$B$2:$B$2001,A21,Data!$O$2:$O$2001,0),0) -> 5.8571429 | E21: =IFERROR(AVERAGEIFS(Data!$J$2:$J$2001,Data!$B$2:$B$2001,A21),0) -> 3.8909091 | F21: =IF(B21>=$B$30*1.25,"High",IF(B21>=$B$30,"Medium","Low")) -> High
A22: PR | B22: =IFERROR(AVERAGEIFS(Data!$M$2:$M$2001,Data!$B$2:$B$2001,A22),0) -> 13.165217 | C22: =IFERROR(SUMIFS(Data!$O$2:$O$2001,Data!$B$2:$B$2001,A22)/COUNTIFS(Data!$B$2:$B$2001,A22),0) -> 0.88695652 | D22: =IFERROR(AVERAGEIFS(Data!$N$2:$N$2001,Data!$B$2:$B$2001,A22,Data!$O$2:$O$2001,0),0) -> 3.9230769 | E22: =IFERROR(AVERAGEIFS(Data!$J$2:$J$2001,Data!$B$2:$B$2001,A22),0) -> 4.226087 | F22: =IF(B22>=$B$30*1.25,"High",IF(B22>=$B$30,"Medium","Low")) -> Medium
A23: SC | B23: =IFERROR(AVERAGEIFS(Data!$M$2:$M$2001,Data!$B$2:$B$2001,A23),0) -> 14.791667 | C23: =IFERROR(SUMIFS(Data!$O$2:$O$2001,Data!$B$2:$B$2001,A23)/COUNTIFS(Data!$B$2:$B$2001,A23),0) -> 0.92708333 | D23: =IFERROR(AVERAGEIFS(Data!$N$2:$N$2001,Data!$B$2:$B$2001,A23,Data!$O$2:$O$2001,0),0) -> 4.5714286 | E23: =IFERROR(AVERAGEIFS(Data!$J$2:$J$2001,Data!$B$2:$B$2001,A23),0) -> 4.15625 | F23: =IF(B23>=$B$30*1.25,"High",IF(B23>=$B$30,"Medium","Low")) -> Medium
A24: BA | B24: =IFERROR(AVERAGEIFS(Data!$M$2:$M$2001,Data!$B$2:$B$2001,A24),0) -> 20.246154 | C24: =IFERROR(SUMIFS(Data!$O$2:$O$2001,Data!$B$2:$B$2001,A24)/COUNTIFS(Data!$B$2:$B$2001,A24),0) -> 0.93846154 | D24: =IFERROR(AVERAGEIFS(Data!$N$2:$N$2001,Data!$B$2:$B$2001,A24,Data!$O$2:$O$2001,0),0) -> 6.5 | E24: =IFERROR(AVERAGEIFS(Data!$J$2:$J$2001,Data!$B$2:$B$2001,A24),0) -> 3.9076923 | F24: =IF(B24>=$B$30*1.25,"High",IF(B24>=$B$30,"Medium","Low")) -> High
A25: DF | B25: =IFERROR(AVERAGEIFS(Data!$M$2:$M$2001,Data!$B$2:$B$2001,A25),0) -> 13.673077 | C25: =IFERROR(SUMIFS(Data!$O$2:$O$2001,Data!$B$2:$B$2001,A25)/COUNTIFS(Data!$B$2:$B$2001,A25),0) -> 0.96153846 | D25: =IFERROR(AVERAGEIFS(Data!$N$2:$N$2001,Data!$B$2:$B$2001,A25,Data!$O$2:$O$2001,0),0) -> 2 | E25: =IFERROR(AVERAGEIFS(Data!$J$2:$J$2001,Data!$B$2:$B$2001,A25),0) -> 4.3269231 | F25: =IF(B25>=$B$30*1.25,"High",IF(B25>=$B$30,"Medium","Low")) -> Medium
A26: GO | B26: =IFERROR(AVERAGEIFS(Data!$M$2:$M$2001,Data!$B$2:$B$2001,A26),0) -> 17.7 | C26: =IFERROR(SUMIFS(Data!$O$2:$O$2001,Data!$B$2:$B$2001,A26)/COUNTIFS(Data!$B$2:$B$2001,A26),0) -> 0.81666667 | D26: =IFERROR(AVERAGEIFS(Data!$N$2:$N$2001,Data!$B$2:$B$2001,A26,Data!$O$2:$O$2001,0),0) -> 6.8181818 | E26: =IFERROR(AVERAGEIFS(Data!$J$2:$J$2001,Data!$B$2:$B$2001,A26),0) -> 3.95 | F26: =IF(B26>=$B$30*1.25,"High",IF(B26>=$B$30,"Medium","Low")) -> High
A27: ES | B27: =IFERROR(AVERAGEIFS(Data!$M$2:$M$2001,Data!$B$2:$B$2001,A27),0) -> 15.969697 | C27: =IFERROR(SUMIFS(Data!$O$2:$O$2001,Data!$B$2:$B$2001,A27)/COUNTIFS(Data!$B$2:$B$2001,A27),0) -> 0.84848485 | D27: =IFERROR(AVERAGEIFS(Data!$N$2:$N$2001,Data!$B$2:$B$2001,A27,Data!$O$2:$O$2001,0),0) -> 4.4 | E27: =IFERROR(AVERAGEIFS(Data!$J$2:$J$2001,Data!$B$2:$B$2001,A27),0) -> 4 | F27: =IF(B27>=$B$30*1.25,"High",IF(B27>=$B$30,"Medium","Low")) -> High
A28: PE | B28: =IFERROR(AVERAGEIFS(Data!$M$2:$M$2001,Data!$B$2:$B$2001,A28),0) -> 23.5 | C28: =IFERROR(SUMIFS(Data!$O$2:$O$2001,Data!$B$2:$B$2001,A28)/COUNTIFS(Data!$B$2:$B$2001,A28),0) -> 0.9047619 | D28: =IFERROR(AVERAGEIFS(Data!$N$2:$N$2001,Data!$B$2:$B$2001,A28,Data!$O$2:$O$2001,0),0) -> 14.25 | E28: =IFERROR(AVERAGEIFS(Data!$J$2:$J$2001,Data!$B$2:$B$2001,A28),0) -> 3.8571429 | F28: =IF(B28>=$B$30*1.25,"High",IF(B28>=$B$30,"Medium","Low")) -> High
A29: CE | B29: =IFERROR(AVERAGEIFS(Data!$M$2:$M$2001,Data!$B$2:$B$2001,A29),0) -> 22.4 | C29: =IFERROR(SUMIFS(Data!$O$2:$O$2001,Data!$B$2:$B$2001,A29)/COUNTIFS(Data!$B$2:$B$2001,A29),0) -> 0.96 | D29: =IFERROR(AVERAGEIFS(Data!$N$2:$N$2001,Data!$B$2:$B$2001,A29,Data!$O$2:$O$2001,0),0) -> 1 | E29: =IFERROR(AVERAGEIFS(Data!$J$2:$J$2001,Data!$B$2:$B$2001,A29),0) -> 4 | F29: =IF(B29>=$B$30*1.25,"High",IF(B29>=$B$30,"Medium","Low")) -> High
A30: All-state average | B30: =AVERAGE(Data!$M$2:$M$2001) -> 12.457
A31: Bottleneck rating: High = avg delivery time 25%+ above the overall average; Medium = above average.

Sheet Category Analysis
A1: Product Category Analysis
A2: Cost ratios are pulled from the Assumptions sheet with INDEX/MATCH.
A4: Category | B4: Orders | C4: Revenue | D4: Net Profit | E4: Profit Margin | F4: Avg Price | G4: Avg Review | H4: Cost Ratio | I4: Profit Rank
A5: bed_bath_table | B5: =COUNTIFS(Data!$F$2:$F$2001,A5) -> 353 | C5: =SUMIFS(Data!$P$2:$P$2001,Data!$F$2:$F$2001,A5) -> 40417.9 | D5: =SUMIFS(Data!$S$2:$S$2001,Data!$F$2:$F$2001,A5) -> 8067.847 | E5: =IFERROR(D5/C5,0) -> 0.19961074 | F5: =IFERROR(AVERAGEIFS(Data!$G$2:$G$2001,Data!$F$2:$F$2001,A5),0) -> 93.422521 | G5: =IFERROR(AVERAGEIFS(Data!$J$2:$J$2001,Data!$F$2:$F$2001,A5),0) -> 4.266289 | H5: =INDEX(Assumptions!$B$8:$B$16,MATCH(A5,Assumptions!$A$8:$A$16,0)) -> 0.62 | I5: =RANK(D5,$D$5:$D$13) -> 2
A6: health_beauty | B6: =COUNTIFS(Data!$F$2:$F$2001,A6) -> 296 | C6: =SUMIFS(Data!$P$2:$P$2001,Data!$F$2:$F$2001,A6) -> 35451.86 | D6: =SUMIFS(Data!$S$2:$S$2001,Data!$F$2:$F$2001,A6) -> 8255.589 | E6: =IFERROR(D6/C6,0) -> 0.23286758 | F6: =IFERROR(AVERAGEIFS(Data!$G$2:$G$2001,Data!$F$2:$F$2001,A6),0) -> 97.796453 | G6: =IFERROR(AVERAGEIFS(Data!$J$2:$J$2001,Data!$F$2:$F$2001,A6),0) -> 4.1824324 | H6: =INDEX(Assumptions!$B$8:$B$16,MATCH(A6,Assumptions!$A$8:$A$16,0)) -> 0.58 | I6: =RANK(D6,$D$5:$D$13) -> 1
A7: sports_leisure | B7: =COUNTIFS(Data!$F$2:$F$2001,A7) -> 248 | C7: =SUMIFS(Data!$P$2:$P$2001,Data!$F$2:$F$2001,A7) -> 31386.84 | D7: =SUMIFS(Data!$S$2:$S$2001,Data!$F$2:$F$2001,A7) -> 6050.9328 | E7: =IFERROR(D7/C7,0) -> 0.19278566 | F7: =IFERROR(AVERAGEIFS(Data!$G$2:$G$2001,Data!$F$2:$F$2001,A7),0) -> 104.51544 | G7: =IFERROR(AVERAGEIFS(Data!$J$2:$J$2001,Data!$F$2:$F$2001,A7),0) -> 4.2459677 | H7: =INDEX(Assumptions!$B$8:$B$16,MATCH(A7,Assumptions!$A$8:$A$16,0)) -> 0.64 | I7: =RANK(D7,$D$5:$D$13) -> 4
A8: furniture_decor | B8: =COUNTIFS(Data!$F$2:$F$2001,A8) -> 218 | C8: =SUMIFS(Data!$P$2:$P$2001,Data!$F$2:$F$2001,A8) -> 29964.94 | D8: =SUMIFS(Data!$S$2:$S$2001,Data!$F$2:$F$2001,A8) -> 4792.062 | E8: =IFERROR(D8/C8,0) -> 0.1599223 | F8: =IFERROR(AVERAGEIFS(Data!$G$2:$G$2001,Data!$F$2:$F$2001,A8),0) -> 116.06028 | G8: =IFERROR(AVERAGEIFS(Data!$J$2:$J$2001,Data!$F$2:$F$2001,A8),0) -> 4.1788991 | H8: =INDEX(Assumptions!$B$8:$B$16,MATCH(A8,Assumptions!$A$8:$A$16,0)) -> 0.7 | I8: =RANK(D8,$D$5:$D$13) -> 5
